<?xml version="1.0" ?>
<!-- =================================================================================== -->
<!-- |    This document was autogenerated by xacro from my_robot.xacro                 | -->
<!-- |    EDITING THIS FILE BY HAND IS NOT RECOMMENDED                                 | -->
<!-- =================================================================================== -->
<robot name="my_robot">
  <material name="white">
    <color rgba="0.8 0.8 0.8 1"/>
  </material>
  <material name="black">
    <color rgba="0.1 0.1 0.1 1"/>
  </material>
  <!-- ****************** ROBOT BASE FOOTPRINT ***************************  -->
  <link name="world"/>
  <joint name="worl_joint" type="fixed">
    <parent link="world"/>
    <child link="base_link"/>
  </joint>
  <!-- ********************** ROBOT BASE *********************************  -->
  <!-- Base Link -->
  <link name="base_link">
    <collision>
      <origin rpy="0 0 0" xyz="0 0 0"/>
      <geometry>
        <box size="0.44 0.5 0.04"/>
      </geometry>
    </collision>
    <visual>
      <origin rpy="0 0 0" xyz="0 0 0"/>
      <geometry>
        <box size="0.44 0.5 0.04"/>
      </geometry>
      <material name="white"/>
    </visual>
    <inertial>
      <origin rpy="0 0 0" xyz="0 0 0"/>
      <mass value="1.0"/>
      <inertia ixx="0.020966666666666665" ixy="0.0" ixz="0.0" iyy="0.016266666666666665" iyz="0.0" izz="0.03696666666666666"/>
    </inertial>
  </link>
  <!-- ****************** ROBOT BASE FOOTPRINT ***************************  -->
  <link name="base_footprint"/>
  <joint name="base_joint" type="fixed">
    <parent link="base_link"/>
    <child link="base_footprint"/>
    <origin rpy="0 0 0" xyz="0 0 -0.045000000000000005"/>
  </joint>
  <joint name="left_wheel_joint" type="continuous">
    <parent link="base_link"/>
    <child link="left_wheel"/>
    <origin rpy="0 0 0" xyz="0.15 0.275 0.04"/>
    <axis xyz="0 1 0"/>
    <dynamics damping="0.2"/>
  </joint>
  <!-- left wheel Link -->
  <link name="left_wheel">
    <collision>
      <origin rpy="1.5707963267948966 0 0" xyz="0 0 0"/>
      <geometry>
        <cylinder length="0.05" radius="0.085"/>
      </geometry>
    </collision>
    <visual>
      <origin rpy="1.5707963267948966 0 0" xyz="0 0 0"/>
      <geometry>
        <cylinder length="0.05" radius="0.085"/>
      </geometry>
      <material name="black"/>
    </visual>
    <inertial>
      <origin rpy="1.5707963267948966 0 0" xyz="0 0 0"/>
      <mass value="1.5"/>
      <inertia ixx="0.0030218750000000003" ixy="0" ixz="0" iyy="0.0030218750000000003" iyz="0" izz="0.005418750000000001"/>
    </inertial>
  </link>
  <joint name="right_wheel_joint" type="continuous">
    <parent link="base_link"/>
    <child link="right_wheel"/>
    <origin rpy="0 0 0" xyz="0.15 -0.275 0.04"/>
    <axis xyz="0 1 0"/>
    <dynamics damping="0.2"/>
  </joint>
  <!-- right wheel Link -->
  <link name="right_wheel">
    <collision>
      <origin rpy="1.5707963267948966 0 0" xyz="0 0 0"/>
      <geometry>
        <cylinder length="0.05" radius="0.085"/>
      </geometry>
    </collision>
    <visual>
      <origin rpy="1.5707963267948966 0 0" xyz="0 0 0"/>
      <geometry>
        <cylinder length="0.05" radius="0.085"/>
      </geometry>
      <material name="black"/>
    </visual>
    <inertial>
      <origin rpy="1.5707963267948966 0 0" xyz="0 0 0"/>
      <mass value="1.5"/>
      <inertia ixx="0.0030218750000000003" ixy="0" ixz="0" iyy="0.0030218750000000003" iyz="0" izz="0.005418750000000001"/>
    </inertial>
  </link>
  <joint name="caster_wheel_joint" type="fixed">
    <parent link="base_link"/>
    <child link="caster_wheel"/>
    <origin rpy="0 0 0" xyz="-0.15 0 -0.01"/>
  </joint>
  <!-- caster wheel Link -->
  <link name="caster_wheel">
    <collision>
      <origin rpy="0 0 0" xyz="0 0 0"/>
      <geometry>
        <sphere radius="0.025"/>
      </geometry>
    </collision>
    <visual>
      <origin rpy="0 0 0" xyz="0 0 0"/>
      <geometry>
        <sphere radius="0.025"/>
      </geometry>
      <material name="black"/>
    </visual>
    <inertial>
      <origin rpy="0 0 0" xyz="0 0 0"/>
      <mass value="0.1"/>
      <inertia ixx="2.500000000000001e-05" ixy="0.0" ixz="0.0" iyy="2.500000000000001e-05" iyz="0.0" izz="2.500000000000001e-05"/>
    </inertial>
  </link>
  <joint name="laser_joint" type="fixed">
    <parent link="base_link"/>
    <child link="laser"/>
    <origin rpy="0 0 0" xyz="-0.200 0.0 0.320 "/>
  </joint>
  <!-- caster left wheel Link -->
  <link name="laser">
    <collision>
      <origin rpy="0 0 0" xyz="0 0 0"/>
      <geometry>
        <box size="0.040 0.040 0.080"/>
      </geometry>
    </collision>
    <visual>
      <origin rpy="0 0 0" xyz="0 0 0"/>
      <geometry>
        <box size="0.040 0.040 0.080"/>
      </geometry>
      <material name="black"/>
    </visual>
  </link>
</robot>
